Workbook

Sheet Dashboard
A1: WORKOUT PROGRAMMING DASHBOARD
A2: Overview of training balance, gaps, and suggested exercises
A4: KEY METRICS | E4: PATTERN BALANCE (Last 7 Days)
A5: Total Workouts (30d) | B5: =COUNTIF('Workout Log'!A4:A500,">="&TODAY()-30) -> 0 | E5: Pattern | F5: Count | G5: Target | H5: Status
A6: Total Workouts (7d) | B6: =COUNTIF('Workout Log'!A4:A500,">="&TODAY()-7) -> 0 | E6: ='Pattern Tracker'!A7 -> Squat | F6: ='Pattern Tracker'!B7 -> 0 | G6: ='Pattern Tracker'!G7 -> 2 | H6: =IF('Pattern Tracker'!H7=0,"OK",IF('Pattern Tracker'!H7>=2,"DEFICIT","LOW")) -> DEFICIT
A7: Avg Duration (min) | B7: =IFERROR(AVERAGEIFS('Workout Log'!E4:E500,'Workout Log'!A4:A500,">="&TODAY()-30),0) -> 0 | E7: ='Pattern Tracker'!A8 -> Hinge | F7: ='Pattern Tracker'!B8 -> 0 | G7: ='Pattern Tracker'!G8 -> 2 | H7: =IF('Pattern Tracker'!H8=0,"OK",IF('Pattern Tracker'!H8>=2,"DEFICIT","LOW")) -> DEFICIT
A8: Avg RPE (30d) | B8: =IFERROR(AVERAGEIFS('Workout Log'!O4:O500,'Workout Log'!A4:A500,">="&TODAY()-30),0) -> 0 | E8: ='Pattern Tracker'!A9 -> Push (Horizontal) | F8: ='Pattern Tracker'!B9 -> 0 | G8: ='Pattern Tracker'!G9 -> 2 | H8: =IF('Pattern Tracker'!H9=0,"OK",IF('Pattern Tracker'!H9>=2,"DEFICIT","LOW")) -> DEFICIT
A9: Biggest Deficit Pattern | B9: =IFERROR(INDEX('Pattern Tracker'!A7:A20,MATCH(MAX('Pattern Tracker'!H7:H20),'Pattern Tracker'!H7:H20,0)),"None") -> Squat | E9: ='Pattern Tracker'!A10 -> Push (Vertical) | F9: ='Pattern Tracker'!B10 -> 0 | G9: ='Pattern Tracker'!G10 -> 2 | H9: =IF('Pattern Tracker'!H10=0,"OK",IF('Pattern Tracker'!H10>=2,"DEFICIT","LOW")) -> DEFICIT
A10: Max Deficit Score | B10: =MAX('Pattern Tracker'!H7:H20) -> 2 | E10: ='Pattern Tracker'!A11 -> Pull (Horizontal) | F10: ='Pattern Tracker'!B11 -> 0 | G10: ='Pattern Tracker'!G11 -> 2 | H10: =IF('Pattern Tracker'!H11=0,"OK",IF('Pattern Tracker'!H11>=2,"DEFICIT","LOW")) -> DEFICIT
E11: ='Pattern Tracker'!A12 -> Pull (Vertical) | F11: ='Pattern Tracker'!B12 -> 0 | G11: ='Pattern Tracker'!G12 -> 2 | H11: =IF('Pattern Tracker'!H12=0,"OK",IF('Pattern Tracker'!H12>=2,"DEFICIT","LOW")) -> DEFICIT
E12: ='Pattern Tracker'!A13 -> Olympic - Snatch | F12: ='Pattern Tracker'!B13 -> 0 | G12: ='Pattern Tracker'!G13 -> 2 | H12: =IF('Pattern Tracker'!H13=0,"OK",IF('Pattern Tracker'!H13>=2,"DEFICIT","LOW")) -> DEFICIT
A13: TOP 10 RECOMMENDED EXERCISES | E13: ='Pattern Tracker'!A14 -> Olympic - Clean | F13: ='Pattern Tracker'!B14 -> 0 | G13: ='Pattern Tracker'!G14 -> 2 | H13: =IF('Pattern Tracker'!H14=0,"OK",IF('Pattern Tracker'!H14>=2,"DEFICIT","LOW")) -> DEFICIT
A14: Rank | B14: Exercise | C14: Coverage Score | E14: ='Pattern Tracker'!A15 -> Olympic - Jerk | F14: ='Pattern Tracker'!B15 -> 0 | G14: ='Pattern Tracker'!G15 -> 2 | H14: =IF('Pattern Tracker'!H15=0,"OK",IF('Pattern Tracker'!H15>=2,"DEFICIT","LOW")) -> DEFICIT
A15: 1 | B15: =IFERROR(INDEX('Need Vector'!A25:A84,MATCH(1,'Need Vector'!E25:E84,0)),"") -> Overhead Squat | C15: =IFERROR(INDEX('Need Vector'!D25:D84,MATCH(1,'Need Vector'!E25:E84,0)),"") -> 0.10714286 | E15: ='Pattern Tracker'!A16 -> Monostructural | F15: ='Pattern Tracker'!B16 -> 0 | G15: ='Pattern Tracker'!G16 -> 2 | H15: =IF('Pattern Tracker'!H16=0,"OK",IF('Pattern Tracker'!H16>=2,"DEFICIT","LOW")) -> DEFICIT
A16: 2 | B16: =IFERROR(INDEX('Need Vector'!A25:A84,MATCH(2,'Need Vector'!E25:E84,0)),"") | C16: =IFERROR(INDEX('Need Vector'!D25:D84,MATCH(2,'Need Vector'!E25:E84,0)),"") | E16: ='Pattern Tracker'!A17 -> Midline | F16: ='Pattern Tracker'!B17 -> 0 | G16: ='Pattern Tracker'!G17 -> 2 | H16: =IF('Pattern Tracker'!H17=0,"OK",IF('Pattern Tracker'!H17>=2,"DEFICIT","LOW")) -> DEFICIT
A17: 3 | B17: =IFERROR(INDEX('Need Vector'!A25:A84,MATCH(3,'Need Vector'!E25:E84,0)),"") | C17: =IFERROR(INDEX('Need Vector'!D25:D84,MATCH(3,'Need Vector'!E25:E84,0)),"") | E17: ='Pattern Tracker'!A18 -> Loaded Carry | F17: ='Pattern Tracker'!B18 -> 0 | G17: ='Pattern Tracker'!G18 -> 2 | H17: =IF('Pattern Tracker'!H18=0,"OK",IF('Pattern Tracker'!H18>=2,"DEFICIT","LOW")) -> DEFICIT
A18: 4 | B18: =IFERROR(INDEX('Need Vector'!A25:A84,MATCH(4,'Need Vector'!E25:E84,0)),"") | C18: =IFERROR(INDEX('Need Vector'!D25:D84,MATCH(4,'Need Vector'!E25:E84,0)),"") | E18: ='Pattern Tracker'!A19 -> Plyometric | F18: ='Pattern Tracker'!B19 -> 0 | G18: ='Pattern Tracker'!G19 -> 2 | H18: =IF('Pattern Tracker'!H19=0,"OK",IF('Pattern Tracker'!H19>=2,"DEFICIT","LOW")) -> DEFICIT
A19: 5 | B19: =IFERROR(INDEX('Need Vector'!A25:A84,MATCH(5,'Need Vector'!E25:E84,0)),"") | C19: =IFERROR(INDEX('Need Vector'!D25:D84,MATCH(5,'Need Vector'!E25:E84,0)),"") | E19: ='Pattern Tracker'!A20 -> Accessory | F19: ='Pattern Tracker'!B20 -> 0 | G19: ='Pattern Tracker'!G20 -> 2 | H19: =IF('Pattern Tracker'!H20=0,"OK",IF('Pattern Tracker'!H20>=2,"DEFICIT","LOW")) -> DEFICIT
A20: 6 | B20: =IFERROR(INDEX('Need Vector'!A25:A84,MATCH(6,'Need Vector'!E25:E84,0)),"") | C20: =IFERROR(INDEX('Need Vector'!D25:D84,MATCH(6,'Need Vector'!E25:E84,0)),"")
A21: 7 | B21: =IFERROR(INDEX('Need Vector'!A25:A84,MATCH(7,'Need Vector'!E25:E84,0)),"") | C21: =IFERROR(INDEX('Need Vector'!D25:D84,MATCH(7,'Need Vector'!E25:E84,0)),"")
A22: 8 | B22: =IFERROR(INDEX('Need Vector'!A25:A84,MATCH(8,'Need Vector'!E25:E84,0)),"") | C22: =IFERROR(INDEX('Need Vector'!D25:D84,MATCH(8,'Need Vector'!E25:E84,0)),"")
A23: 9 | B23: =IFERROR(INDEX('Need Vector'!A25:A84,MATCH(9,'Need Vector'!E25:E84,0)),"") | C23: =IFERROR(INDEX('Need Vector'!D25:D84,MATCH(9,'Need Vector'!E25:E84,0)),"")
A24: 10 | B24: =IFERROR(INDEX('Need Vector'!A25:A84,MATCH(10,'Need Vector'!E25:E84,0)),"") | C24: =IFERROR(INDEX('Need Vector'!D25:D84,MATCH(10,'Need Vector'!E25:E84,0)),"")

Sheet Exercise Library
A1: EXERCISE LIBRARY
A2: Master list of exercises with movement pattern classifications
A3: Exercise ID | B3: Exercise Name | C3: Primary Pattern | D3: Secondary Pattern | E3: Equipment | F3: Load Type | G3: Laterality | H3: Energy System | I3: Complexity | J3: Notes
A4: EX001 | B4: Back Squat | C4: Squat | E4: Barbell | F4: Heavy | G4: Bilateral | H4: Phosphagen | I4: Low
A5: EX002 | B5: Front Squat | C5: Squat | E5: Barbell | F5: Heavy | G5: Bilateral | H5: Phosphagen | I5: Medium
A6: EX003 | B6: Overhead Squat | C6: Squat | D6: Push (Vertical) | E6: Barbell | F6: Moderate | G6: Bilateral | H6: Phosphagen | I6: High
A7: EX004 | B7: Air Squat | C7: Squat | E7: Bodyweight | F7: Bodyweight | G7: Bilateral | H7: Mixed | I7: Low
A8: EX005 | B8: Pistol Squat | C8: Squat | D8: Midline | E8: Bodyweight | F8: Bodyweight | G8: Unilateral | H8: Mixed | I8: High
A9: EX006 | B9: Wall Ball | C9: Squat | D9: Push (Vertical) | E9: Medicine Ball | F9: Light | G9: Bilateral | H9: Glycolytic | I9: Low
A10: EX007 | B10: Thruster | C10: Squat | D10: Push (Vertical) | E10: Barbell | F10: Moderate | G10: Bilateral | H10: Glycolytic | I10: Medium
A11: EX008 | B11: Deadlift | C11: Hinge | E11: Barbell | F11: Heavy | G11: Bilateral | H11: Phosphagen | I11: Low
A12: EX009 | B12: Romanian Deadlift | C12: Hinge | E12: Barbell | F12: Moderate | G12: Bilateral | H12: Phosphagen | I12: Low
A13: EX010 | B13: Kettlebell Swing | C13: Hinge | D13: Midline | E13: Kettlebell | F13: Moderate | G13: Bilateral | H13: Glycolytic | I13: Low
A14: EX011 | B14: GHD Hip Extension | C14: Hinge | D14: Midline | E14: Machine | F14: Bodyweight | G14: Bilateral | H14: Phosphagen | I14: Medium
A15: EX012 | B15: Single-Leg RDL | C15: Hinge | E15: Dumbbell | F15: Moderate | G15: Unilateral | H15: Phosphagen | I15: Medium
A16: EX013 | B16: Strict Press | C16: Push (Vertical) | E16: Barbell | F16: Heavy | G16: Bilateral | H16: Phosphagen | I16: Low
A17: EX014 | B17: Push Press | C17: Push (Vertical) | D17: Squat | E17: Barbell | F17: Moderate | G17: Bilateral | H17: Glycolytic | I17: Medium
A18: EX015 | B18: Push Jerk | C18: Push (Vertical) | D18: Squat | E18: Barbell | F18: Moderate | G18: Bilateral | H18: Glycolytic | I18: Medium
A19: EX016 | B19: Handstand Push-Up | C19: Push (Vertical) | D19: Midline | E19: Bodyweight | F19: Bodyweight | G19: Bilateral | H19: Phosphagen | I19: High
A20: EX017 | B20: Bench Press | C20: Push (Horizontal) | E20: Barbell | F20: Heavy | G20: Bilateral | H20: Phosphagen | I20: Low
A21: EX018 | B21: Push-Up | C21: Push (Horizontal) | D21: Midline | E21: Bodyweight | F21: Bodyweight | G21: Bilateral | H21: Mixed | I21: Low
A22: EX019 | B22: Ring Dip | C22: Push (Vertical) | D22: Midline | E22: Rig/Bar | F22: Bodyweight | G22: Bilateral | H22: Phosphagen | I22: High
A23: EX020 | B23: Pull-Up | C23: Pull (Vertical) | E23: Rig/Bar | F23: Bodyweight | G23: Bilateral | H23: Mixed | I23: Medium
A24: EX021 | B24: Chest-to-Bar Pull-Up | C24: Pull (Vertical) | E24: Rig/Bar | F24: Bodyweight | G24: Bilateral | H24: Mixed | I24: High
A25: EX022 | B25: Muscle-Up (Bar) | C25: Pull (Vertical) | D25: Push (Vertical) | E25: Rig/Bar | F25: Bodyweight | G25: Bilateral | H25: Glycolytic | I25: High
A26: EX023 | B26: Muscle-Up (Ring) | C26: Pull (Vertical) | D26: Push (Vertical) | E26: Rig/Bar | F26: Bodyweight | G26: Bilateral | H26: Glycolytic | I26: High
A27: EX024 | B27: Toes-to-Bar | C27: Midline | D27: Pull (Vertical) | E27: Rig/Bar | F27: Bodyweight | G27: Bilateral | H27: Glycolytic | I27: Medium
A28: EX025 | B28: Barbell Row | C28: Pull (Horizontal) | E28: Barbell | F28: Moderate | G28: Bilateral | H28: Phosphagen | I28: Low
A29: EX026 | B29: Ring Row | C29: Pull (Horizontal) | E29: Rig/Bar | F29: Bodyweight | G29: Bilateral | H29: Mixed | I29: Low
A30: EX027 | B30: Snatch | C30: Olympic - Snatch | E30: Barbell | F30: Heavy | G30: Bilateral | H30: Phosphagen | I30: High
A31: EX028 | B31: Power Snatch | C31: Olympic - Snatch | D31: Hinge | E31: Barbell | F31: Moderate | G31: Bilateral | H31: Phosphagen | I31: High
A32: EX029 | B32: Snatch Pull | C32: Olympic - Snatch | D32: Hinge | E32: Barbell | F32: Heavy | G32: Bilateral | H32: Phosphagen | I32: Medium
A33: EX030 | B33: Hang Snatch | C33: Olympic - Snatch | E33: Barbell | F33: Moderate | G33: Bilateral | H33: Phosphagen | I33: High
A34: EX031 | B34: Clean | C34: Olympic - Clean | E34: Barbell | F34: Heavy | G34: Bilateral | H34: Phosphagen | I34: High
A35: EX032 | B35: Power Clean | C35: Olympic - Clean | D35: Hinge | E35: Barbell | F35: Moderate | G35: Bilateral | H35: Phosphagen | I35: High
A36: EX033 | B36: Hang Clean | C36: Olympic - Clean | E36: Barbell | F36: Moderate | G36: Bilateral | H36: Phosphagen | I36: High
A37: EX034 | B37: Clean Pull | C37: Olympic - Clean | D37: Hinge | E37: Barbell | F37: Heavy | G37: Bilateral | H37: Phosphagen | I37: Medium
A38: EX035 | B38: Split Jerk | C38: Olympic - Jerk | D38: Push (Vertical) | E38: Barbell | F38: Heavy | G38: Bilateral | H38: Phosphagen | I38: High
A39: EX036 | B39: Clean & Jerk | C39: Olympic - Clean | D39: Olympic - Jerk | E39: Barbell | F39: Heavy | G39: Bilateral | H39: Phosphagen | I39: High
A40: EX037 | B40: Running | C40: Monostructural | E40: None | F40: Bodyweight | G40: Bilateral | H40: Oxidative | I40: Low
...

Sheet Workout Log
A1: WORKOUT LOG
A2: Log each workout. Pick exercises from the Exercise Library dropdown.
A3: Date | B3: Workout ID | C3: Workout Type | D3: WOD Format | E3: Duration (min) | F3: Exercise 1 | G3: Exercise 2 | H3: Exercise 3 | I3: Exercise 4 | J3: Exercise 5 | K3: Exercise 6 | L3: Exercise 7 | M3: Exercise 8 | N3: Score/Result | O3: RPE (1-10) | P3: Notes
B4: =IF(A4="","","WOD-"&TEXT(ROW()-3,"000"))
B5: =IF(A5="","","WOD-"&TEXT(ROW()-3,"000"))
B6: =IF(A6="","","WOD-"&TEXT(ROW()-3,"000"))
B7: =IF(A7="","","WOD-"&TEXT(ROW()-3,"000"))
B8: =IF(A8="","","WOD-"&TEXT(ROW()-3,"000"))
B9: =IF(A9="","","WOD-"&TEXT(ROW()-3,"000"))
B10: =IF(A10="","","WOD-"&TEXT(ROW()-3,"000"))
B11: =IF(A11="","","WOD-"&TEXT(ROW()-3,"000"))
B12: =IF(A12="","","WOD-"&TEXT(ROW()-3,"000"))
B13: =IF(A13="","","WOD-"&TEXT(ROW()-3,"000"))
B14: =IF(A14="","","WOD-"&TEXT(ROW()-3,"000"))
B15: =IF(A15="","","WOD-"&TEXT(ROW()-3,"000"))
... B53: =IF(A53="","","WOD-"&TEXT(ROW()-3,"000"))

Sheet Pattern Tracker
A1: MOVEMENT PATTERN TRACKER
A2: Counts how often each movement pattern appears in your log (last 7, 14, 30 days)
A4: Today's Date: | B4: =TODAY() -> 46085
A6: Movement Pattern | B6: Last 7 Days | C6: Last 14 Days | D6: Last 30 Days | E6: Total (All Time) | F6: Days Since Last | G6: Ideal Freq / 7d | H6: Deficit Score
A7: Squat | B7: =SUMPRODUCT(('Workout Log'!$A$4:$A$500>=TODAY()-7)*('Workout Log'!$A$4:$A$500<>"")*(IFERROR(VLOOKUP('Workout Log'!F$4:F$500,'Exercise Library'!$B$4:$C$200,2,FALSE()),"")=A7))+SUMPRODUCT(('Workout Log'!$A$4:$A$500>=TODAY()-7)*('Workout Log'!$A$4:$A$500<>"")*(IFERROR(VLOOKUP('Workout Log'!F$4:F$500,'Exercise Library'!$B$4:$D$200,3,FALSE()),"")=A7))+SUMPRODUCT(('Workout Log'!$A$4:$A$500>=TODAY()-7)*('Workout Log'!$A$4:$A$500<>"")*(IFERROR(VLOOKUP('Workout Log'!G$4:G$500,'Exercise Library'!$B$4:$C$200,2,FALSE()),"")=A7))+SUMPRODUCT(('Workout Log'!$A$4:$A$500>=TODAY()-7)*('Workout Log'!$A$4:$A$500<>"")*(IFERROR(VLOOKUP('Workout Log'!G$4:G$500,'Exercise Library'!$B$4:$D$200,3,FALSE()),"")=A7))+SUMPRODUCT(('Workout Log'!$A$4:$A$500>=TODAY()-7)*('Workout Log'!$A$4:$A$500<>"")*(IFERROR(VLOOKUP('Workout Log'!H$4:H$500,'Exercise Library'!$B$4:$C$200,2,FALSE()),"")=A7))+SUMPRODUCT(('Workout Log'!$A$4:$A$500>=TODAY()-7)*('Workout Log'!$A$4:$A$500<>"")*(IFERROR(VLOOKUP('Workout Log'!H$4:H$500,'Exercise Library'!$B$4:$D$200,3,FALSE()),"")=A7))+SUMPRODUCT(('Workout Log'!$A$4:$A$500>=TODAY()-7)*('Workout Log'!$A$4:$A$500<>"")*(IFERROR(VLOOKUP('Workout Log'!I$4:I$500,'Exercise Library'!$B$4:$C$200,2,FALSE()),"")=A7))+SUMPRODUCT(('Workout Log'!$A$4:$A$500>=TODAY()-7)*('Workout Log'!$A$4:$A$500<>"")*(IFERROR(VLOOKUP('Workout Log'!I$4:I$500,'Exercise Library'!$B$4:$D$200,3,FALSE()),"")=A7))+SUMPRODUCT(('Workout Log'!$A$4:$A$500>=TODAY()-7)*('Workout Log'!$A$4:$A$500<>"")*(IFERROR(VLOOKUP('Workout Log'!J$4:J$500,'Exercise Library'!$B$4:$C$200,2,FALSE()),"")=A7))+SUMPRODUCT(('Workout Log'!$A$4:$A$500>=TODAY()-7)*('Workout Log'!$A$4:$A$500<>"")*(IFERROR(VLOOKUP('Workout Log'!J$4:J$500,'Exercise Library'!$B$4:$D$200,3,FALSE()),"")=A7))+SUMPRODUCT(('Workout Log'!$A$4:$A$500>=TODAY()-7)*('Workout Log'!$A$4:$A$500<>"")*(IFERROR(VLOOKUP('Workout Log'!K$4:K$500,'Exercise Library'!$B$4:$C$200,2,FALSE()),"")=A7))+SUMPRODUCT(('Workout Log'!$A$4:$A$500>=TODAY()-7)*('Workout Log'!$A$4:$A$500<>"")*(IFERROR(VLOOKUP('Workout Log'!K$4:K$500,'Exercise Library'!$B$4:$D$200,3,FALSE()),"")=A7))+SUMPRODUCT(('Workout Log'!$A$4:$A$500>=TODAY()-7)*('Workout Log'!$A$4:$A$500<>"")*(IFERROR(VLOOKUP('Workout Log'!L$4:L$500,'Exercise Library'!$B$4:$C$200,2,FALSE()),"")=A7))+SUMPRODUCT(('Workout Log'!$A$4:$A$500>=TODAY()-7)*('Workout Log'!$A$4:$A$500<>"")*(IFERROR(VLOOKUP('Workout Log'!L$4:L$500,'Exercise Library'!$B$4:$D$200,3,FALSE()),"")=A7))+SUMPRODUCT(('Workout Log'!$A$4:$A$500>=TODAY()-7)*('Workout Log'!$A$4:$A$500<>"")*(IFERROR(VLOOKUP('Workout Log'!M$4:M$500,'Exercise Library'!$B$4:$C$200,2,FALSE()),"")=A7))+SUMPRODUCT(('Workout Log'!$A$4:$A$500>=TODAY()-7)*('Workout Log'!$A$4:$A$500<>"")*(IFERROR(VLOOKUP('Workout Log'!M$4:M$500,'Exercise Library'!$B$4:$D$200,3,FALSE()),"")=A7)) -> 0 | C7: =SUMPRODUCT(('Workout Log'!$A$4:$A$500>=TODAY()-14)*('Workout Log'!$A$4:$A$500<>"")*(IFERROR(VLOOKUP('Workout Log'!F$4:F$500,'Exercise Library'!$B$4:$C$200,2,FALSE()),"")=A7))+SUMPRODUCT(('Workout Log'!$A$4:$A$500>=TODAY()-14)*('Workout Log'!$A$4:$A$500<>"")*(IFERROR(VLOOKUP('Workout Log'!F$4:F$500,'Exercise Library'!$B$4:$D$200,3,FALSE()),"")=A7))+SUMPRODUCT(('Workout Log'!$A$4:$A$500>=TODAY()-14)*('Workout Log'!$A$4:$A$500<>"")*(IFERROR(VLOOKUP('Workout Log'!G$4:G$500,'Exercise Library'!$B$4:$C$200,2,FALSE()),"")=A7))+SUMPRODUCT(('Workout Log'!$A$4:$A$500>=TODAY()-14)*('Workout Log'!$A$4:$A$500<>"")*(IFERROR(VLOOKUP('Workout Log'!G$4:G$500,'Exercise Library'!$B$4:$D$200,3,FALSE()),"")=A7))+SUMPRODUCT(('Workout Log'!$A$4:$A$500>=TODAY()-14)*('Workout Log'!$A$4:$A$500<>"")*(IFERROR(VLOOKUP('Workout Log'!H$4:H$500,'Exercise Library'!$B$4:$C$200,2,FALSE()),"")=A7))+SUMPRODUCT(('Workout Log'!$A$4:$A$500>=TODAY()-14)*('Workout Log'!$A$4:$A$500<>"")*(IFERROR(VLOOKUP('Workout Log'!H$4:H$500,'Exercise Library'!$B$4:$D$200,3,FALSE()),"")=A7))+SUMPRODUCT(('Workout Log'!$A$4:$A$500>=TODAY()-14)*('Workout Log'!$A$4:$A$500<>"")*(IFERROR(VLOOKUP('Workout Log'!I$4:I$500,'Exercise Library'!$B$4:$C$200,2,FALSE()),"")=A7))+SUMPRODUCT(('Workout Log'!$A$4:$A$500>=TODAY()-14)*('Workout Log'!$A$4:$A$500<>"")*(IFERROR(VLOOKUP('Workout Log'!I$4:I$500,'Exercise Library'!$B$4:$D$200,3,FALSE()),"")=A7))+SUMPRODUCT(('Workout Log'!$A$4:$A$500>=TODAY()-14)*('Workout Log'!$A$4:$A$500<>"")*(IFERROR(VLOOKUP('Workout Log'!J$4:J$500,'Exercise Library'!$B$4:$C$200,2,FALSE()),"")=A7))+SUMPRODUCT(('Workout Log'!$A$4:$A$500>=TODAY()-14)*('Workout Log'!$A$4:$A$500<>"")*(IFERROR(VLOOKUP('Workout Log'!J$4:J$500,'Exercise Library'!$B$4:$D$200,3,FALSE()),"")=A7))+SUMPRODUCT(('Workout Log'!$A$4:$A$500>=TODAY()-14)*('Workout Log'!$A$4:$A$500<>"")*(IFERROR(VLOOKUP('Workout Log'!K$4:K$500,'Exercise Library'!$B$4:$C$200,2,FALSE()),"")=A7))+SUMPRODUCT(('Workout Log'!$A$4:$A$500>=TODAY()-14)*('Workout Log'!$A$4:$A$500<>"")*(IFERROR(VLOOKUP('Workout Log'!K$4:K$500,'Exercise Library'!$B$4:$D$200,3,FALSE()),"")=A7))+SUMPRODUCT(('Workout Log'!$A$4:$A$500>=TODAY()-14)*('Workout Log'!$A$4:$A$500<>"")*(IFERROR(VLOOKUP('Workout Log'!L$4:L$500,'Exercise Library'!$B$4:$C$200,2,FALSE()),"")=A7))+SUMPRODUCT(('Workout Log'!$A$4:$A$500>=TODAY()-14)*('Workout Log'!$A$4:$A$500<>"")*(IFERROR(VLOOKUP('Workout Log'!L$4:L$500,'Exercise Library'!$B$4:$D$200,3,FALSE()),"")=A7))+SUMPRODUCT(('Workout Log'!$A$4:$A$500>=TODAY()-14)*('Workout Log'!$A$4:$A$500<>"")*(IFERROR(VLOOKUP('Workout Log'!M$4:M$500,'Exercise Library'!$B$4:$C$200,2,FALSE()),"")=A7))+SUMPRODUCT(('Workout Log'!$A$4:$A$500>=TODAY()-14)*('Workout Log'!$A$4:$A$500<>"")*(IFERROR(VLOOKUP('Workout Log'!M$4:M$500,'Exercise Library'!$B$4:$D$200,3,FALSE()),"")=A7)) -> 0 | D7: =SUMPRODUCT(('Workout Log'!$A$4:$A$500>=TODAY()-30)*('Workout Log'!$A$4:$A$500<>"")*(IFERROR(VLOOKUP('Workout Log'!F$4:F$500,'Exercise Library'!$B$4:$C$200,2,FALSE()),"")=A7))+SUMPRODUCT(('Workout Log'!$A$4:$A$500>=TODAY()-30)*('Workout Log'!$A$4:$A$500<>"")*(IFERROR(VLOOKUP('Workout Log'!F$4:F$500,'Exercise Library'!$B$4:$D$200,3,FALSE()),"")=A7))+SUMPRODUCT(('Workout Log'!$A$4:$A$500>=TODAY()-30)*('Workout Log'!$A$4:$A$500<>"")*(IFERROR(VLOOKUP('Workout Log'!G$4:G$500,'Exercise Library'!$B$4:$C$200,2,FALSE()),"")=A7))+SUMPRODUCT(('Workout Log'!$A$4:$A$500>=TODAY()-30)*('Workout Log'!$A$4:$A$500<>"")*(IFERROR(VLOOKUP('Workout Log'!G$4:G$500,'Exercise Library'!$B$4:$D$200,3,FALSE()),"")=A7))+SUMPRODUCT(('Workout Log'!$A$4:$A$500>=TODAY()-30)*('Workout Log'!$A$4:$A$500<>"")*(IFERROR(VLOOKUP('Workout Log'!H$4:H$500,'Exercise Library'!$B$4:$C$200,2,FALSE()),"")=A7))+SUMPRODUCT(('Workout Log'!$A$4:$A$500>=TODAY()-30)*('Workout Log'!$A$4:$A$500<>"")*(IFERROR(VLOOKUP('Workout Log'!H$4:H$500,'Exercise Library'!$B$4:$D$200,3,FALSE()),"")=A7))+SUMPRODUCT(('Workout Log'!$A$4:$A$500>=TODAY()-30)*('Workout Log'!$A$4:$A$500<>"")*(IFERROR(VLOOKUP('Workout Log'!I$4:I$500,'Exercise Library'!$B$4:$C$200,2,FALSE()),"")=A7))+SUMPRODUCT(('Workout Log'!$A$4:$A$500>=TODAY()-30)*('Workout Log'!$A$4:$A$500<>"")*(IFERROR(VLOOKUP('Workout Log'!I$4:I$500,'Exercise Library'!$B$4:$D$200,3,FALSE()),"")=A7))+SUMPRODUCT(('Workout Log'!$A$4:$A$500>=TODAY()-30)*('Workout Log'!$A$4:$A$500<>"")*(IFERROR(VLOOKUP('Workout Log'!J$4:J$500,'Exercise Library'!$B$4:$C$200,2,FALSE()),"")=A7))+SUMPRODUCT(('Workout Log'!$A$4:$A$500>=TODAY()-30)*('Workout Log'!$A$4:$A$500<>"")*(IFERROR(VLOOKUP('Workout Log'!J$4:J$500,'Exercise Library'!$B$4:$D$200,3,FALSE()),"")=A7))+SUMPRODUCT(('Workout Log'!$A$4:$A$500>=TODAY()-30)*('Workout Log'!$A$4:$A$500<>"")*(IFERROR(VLOOKUP('Workout Log'!K$4:K$500,'Exercise Library'!$B$4:$C$200,2,FALSE()),"")=A7))+SUMPRODUCT(('Workout Log'!$A$4:$A$500>=TODAY()-30)*('Workout Log'!$A$4:$A$500<>"")*(IFERROR(VLOOKUP('Workout Log'!K$4:K$500,'Exercise Library'!$B$4:$D$200,3,FALSE()),"")=A7))+SUMPRODUCT(('Workout Log'!$A$4:$A$500>=TODAY()-30)*('Workout Log'!$A$4:$A$500<>"")*(IFERROR(VLOOKUP('Workout Log'!L$4:L$500,'Exercise Library'!$B$4:$C$200,2,FALSE()),"")=A7))+SUMPRODUCT(('Workout Log'!$A$4:$A$500>=TODAY()-30)*('Workout Log'!$A$4:$A$500<>"")*(IFERROR(VLOOKUP('Workout Log'!L$4:L$500,'Exercise Library'!$B$4:$D$200,3,FALSE()),"")=A7))+SUMPRODUCT(('Workout Log'!$A$4:$A$500>=TODAY()-30)*('Workout Log'!$A$4:$A$500<>"")*(IFERROR(VLOOKUP('Workout Log'!M$4:M$500,'Exercise Library'!$B$4:$C$200,2,FALSE()),"")=A7))+SUMPRODUCT(('Workout Log'!$A$4:$A$500>=TODAY()-30)*('Workout Log'!$A$4:$A$500<>"")*(IFERROR(VLOOKUP('Workout Log'!M$4:M$500,'Exercise Library'!$B$4:$D$200,3,FALSE()),"")=A7)) -> 0 | E7: =SUMPRODUCT(('Workout Log'!$A$4:$A$500>0)*('Workout Log'!$A$4:$A$500<>"")*(IFERROR(VLOOKUP('Workout Log'!F$4:F$500,'Exercise Library'!$B$4:$C$200,2,FALSE()),"")=A7))+SUMPRODUCT(('Workout Log'!$A$4:$A$500>0)*('Workout Log'!$A$4:$A$500<>"")*(IFERROR(VLOOKUP('Workout Log'!F$4:F$500,'Exercise Library'!$B$4:$D$200,3,FALSE()),"")=A7))+SUMPRODUCT(('Workout Log'!$A$4:$A$500>0)*('Workout Log'!$A$4:$A$500<>"")*(IFERROR(VLOOKUP('Workout Log'!G$4:G$500,'Exercise Library'!$B$4:$C$200,2,FALSE()),"")=A7))+SUMPRODUCT(('Workout Log'!$A$4:$A$500>0)*('Workout Log'!$A$4:$A$500<>"")*(IFERROR(VLOOKUP('Workout Log'!G$4:G$500,'Exercise Library'!$B$4:$D$200,3,FALSE()),"")=A7))+SUMPRODUCT(('Workout Log'!$A$4:$A$500>0)*('Workout Log'!$A$4:$A$500<>"")*(IFERROR(VLOOKUP('Workout Log'!H$4:H$500,'Exercise Library'!$B$4:$C$200,2,FALSE()),"")=A7))+SUMPRODUCT(('Workout Log'!$A$4:$A$500>0)*('Workout Log'!$A$4:$A$500<>"")*(IFERROR(VLOOKUP('Workout Log'!H$4:H$500,'Exercise Library'!$B$4:$D$200,3,FALSE()),"")=A7))+SUMPRODUCT(('Workout Log'!$A$4:$A$500>0)*('Workout Log'!$A$4:$A$500<>"")*(IFERROR(VLOOKUP('Workout Log'!I$4:I$500,'Exercise Library'!$B$4:$C$200,2,FALSE()),"")=A7))+SUMPRODUCT(('Workout Log'!$A$4:$A$500>0)*('Workout Log'!$A$4:$A$500<>"")*(IFERROR(VLOOKUP('Workout Log'!I$4:I$500,'Exercise Library'!$B$4:$D$200,3,FALSE()),"")=A7))+SUMPRODUCT(('Workout Log'!$A$4:$A$500>0)*('Workout Log'!$A$4:$A$500<>"")*(IFERROR(VLOOKUP('Workout Log'!J$4:J$500,'Exercise Library'!$B$4:$C$200,2,FALSE()),"")=A7))+SUMPRODUCT(('Workout Log'!$A$4:$A$500>0)*('Workout Log'!$A$4:$A$500<>"")*(IFERROR(VLOOKUP('Workout Log'!J$4:J$500,'Exercise Library'!$B$4:$D$200,3,FALSE()),"")=A7))+SUMPRODUCT(('Workout Log'!$A$4:$A$500>0)*('Workout Log'!$A$4:$A$500<>"")*(IFERROR(VLOOKUP('Workout Log'!K$4:K$500,'Exercise Library'!$B$4:$C$200,2,FALSE()),"")=A7))+SUMPRODUCT(('Workout Log'!$A$4:$A$500>0)*('Workout Log'!$A$4:$A$500<>"")*(IFERROR(VLOOKUP('Workout Log'!K$4:K$500,'Exercise Library'!$B$4:$D$200,3,FALSE()),"")=A7))+SUMPRODUCT(('Workout Log'!$A$4:$A$500>0)*('Workout Log'!$A$4:$A$500<>"")*(IFERROR(VLOOKUP('Workout Log'!L$4:L$500,'Exercise Library'!$B$4:$C$200,2,FALSE()),"")=A7))+SUMPRODUCT(('Workout Log'!$A$4:$A$500>0)*('Workout Log'!$A$4:$A$500<>"")*(IFERROR(VLOOKUP('Workout Log'!L$4:L$500,'Exercise Library'!$B$4:$D$200,3,FALSE()),"")=A7))+SUMPRODUCT(('Workout Log'!$A$4:$A$500>0)*('Workout Log'!$A$4:$A$500<>"")*(IFERROR(VLOOKUP('Workout Log'!M$4:M$500,'Exercise Library'!$B$4:$C$200,2,FALSE()),"")=A7))+SUMPRODUCT(('Workout Log'!$A$4:$A$500>0)*('Workout Log'!$A$4:$A$500<>"")*(IFERROR(VLOOKUP('Workout Log'!M$4:M$500,'Exercise Library'!$B$4:$D$200,3,FALSE()),"")=A7)) -> 0 | F7: =IF(E7=0,"Never",IFERROR(TODAY()-MAX(B7*0+TODAY()-7),"N/A")) -> Never | G7: 2 | H7: =MAX(0, G7-B7) -> 2
A8: Hinge | B8: =SUMPRODUCT(('Workout Log'!$A$4:$A$500>=TODAY()-7)*('Workout Log'!$A$4:$A$500<>"")*(IFERROR(VLOOKUP('Workout Log'!F$4:F$500,'Exercise Library'!$B$4:$C$200,2,FALSE()),"")=A8))+SUMPRODUCT(('Workout Log'!$A$4:$A$500>=TODAY()-7)*('Workout Log'!$A$4:$A$500<>"")*(IFERROR(VLOOKUP('Workout Log'!F$4:F$500,'Exercise Library'!$B$4:$D$200,3,FALSE()),"")=A8))+SUMPRODUCT(('Workout Log'!$A$4:$A$500>=TODAY()-7)*('Workout Log'!$A$4:$A$500<>"")*(IFERROR(VLOOKUP('Workout Log'!G$4:G$500,'Exercise Library'!$B$4:$C$200,2,FALSE()),"")=A8))+SUMPRODUCT(('Workout Log'!$A$4:$A$500>=TODAY()-7)*('Workout Log'!$A$4:$A$500<>"")*(IFERROR(VLOOKUP('Workout Log'!G$4:G$500,'Exercise Library'!$B$4:$D$200,3,FALSE()),"")=A8))+SUMPRODUCT(('Workout Log'!$A$4:$A$500>=TODAY()-7)*('Workout Log'!$A$4:$A$500<>"")*(IFERROR(VLOOKUP('Workout Log'!H$4:H$500,'Exercise Library'!$B$4:$C$200,2,FALSE()),"")=A8))+SUMPRODUCT(('Workout Log'!$A$4:$A$500>=TODAY()-7)*('Workout Log'!$A$4:$A$500<>"")*(IFERROR(VLOOKUP('Workout Log'!H$4:H$500,'Exercise Library'!$B$4:$D$200,3,FALSE()),"")=A8))+SUMPRODUCT(('Workout Log'!$A$4:$A$500>=TODAY()-7)*('Workout Log'!$A$4:$A$500<>"")*(IFERROR(VLOOKUP('Workout Log'!I$4:I$500,'Exercise Library'!$B$4:$C$200,2,FALSE()),"")=A8))+SUMPRODUCT(('Workout Log'!$A$4:$A$500>=TODAY()-7)*('Workout Log'!$A$4:$A$500<>"")*(IFERROR(VLOOKUP('Workout Log'!I$4:I$500,'Exercise Library'!$B$4:$D$200,3,FALSE()),"")=A8))+SUMPRODUCT(('Workout Log'!$A$4:$A$500>=TODAY()-7)*('Workout Log'!$A$4:$A$500<>"")*(IFERROR(VLOOKUP('Workout Log'!J$4:J$500,'Exercise Library'!$B$4:$C$200,2,FALSE()),"")=A8))+SUMPRODUCT(('Workout Log'!$A$4:$A$500>=TODAY()-7)*('Workout Log'!$A$4:$A$500<>"")*(IFERROR(VLOOKUP('Workout Log'!J$4:J$500,'Exercise Library'!$B$4:$D$200,3,FALSE()),"")=A8))+SUMPRODUCT(('Workout Log'!$A$4:$A$500>=TODAY()-7)*('Workout Log'!$A$4:$A$500<>"")*(IFERROR(VLOOKUP('Workout Log'!K$4:K$500,'Exercise Library'!$B$4:$C$200,2,FALSE()),"")=A8))+SUMPRODUCT(('Workout Log'!$A$4:$A$500>=TODAY()-7)*('Workout Log'!$A$4:$A$500<>"")*(IFERROR(VLOOKUP('Workout Log'!K$4:K$500,'Exercise Library'!$B$4:$D$200,3,FALSE()),"")=A8))+SUMPRODUCT(('Workout Log'!$A$4:$A$500>=TODAY()-7)*('Workout Log'!$A$4:$A$500<>"")*(IFERROR(VLOOKUP('Workout Log'!L$4:L$500,'Exercise Library'!$B$4:$C$200,2,FALSE()),"")=A8))+SUMPRODUCT(('Workout Log'!$A$4:$A$500>=TODAY()-7)*('Workout Log'!$A$4:$A$500<>"")*(IFERROR(VLOOKUP('Workout Log'!L$4:L$500,'Exercise Library'!$B$4:$D$200,3,FALSE()),"")=A8))+SUMPRODUCT(('Workout Log'!$A$4:$A$500>=TODAY()-7)*('Workout Log'!$A$4:$A$500<>"")*(IFERROR(VLOOKUP('Workout Log'!M$4:M$500,'Exercise Library'!$B$4:$C$200,2,FALSE()),"")=A8))+SUMPRODUCT(('Workout Log'!$A$4:$A$500>=TODAY()-7)*('Workout Log'!$A$4:$A$500<>"")*(IFERROR(VLOOKUP('Workout Log'!M$4:M$500,'Exercise Library'!$B$4:$D$200,3,FALSE()),"")=A8)) -> 0 | C8: =SUMPRODUCT(('Workout Log'!$A$4:$A$500>=TODAY()-14)*('Workout Log'!$A$4:$A$500<>"")*(IFERROR(VLOOKUP('Workout Log'!F$4:F$500,'Exercise Library'!$B$4:$C$200,2,FALSE()),"")=A8))+SUMPRODUCT(('Workout Log'!$A$4:$A$500>=TODAY()-14)*('Workout Log'!$A$4:$A$500<>"")*(IFERROR(VLOOKUP('Workout Log'!F$4:F$500,'Exercise Library'!$B$4:$D$200,3,FALSE()),"")=A8))+SUMPRODUCT(('Workout Log'!$A$4:$A$500>=TODAY()-14)*('Workout Log'!$A$4:$A$500<>"")*(IFERROR(VLOOKUP('Workout Log'!G$4:G$500,'Exercise Library'!$B$4:$C$200,2,FALSE()),"")=A8))+SUMPRODUCT(('Workout Log'!$A$4:$A$500>=TODAY()-14)*('Workout Log'!$A$4:$A$500<>"")*(IFERROR(VLOOKUP('Workout Log'!G$4:G$500,'Exercise Library'!$B$4:$D$200,3,FALSE()),"")=A8))+SUMPRODUCT(('Workout Log'!$A$4:$A$500>=TODAY()-14)*('Workout Log'!$A$4:$A$500<>"")*(IFERROR(VLOOKUP('Workout Log'!H$4:H$500,'Exercise Library'!$B$4:$C$200,2,FALSE()),"")=A8))+SUMPRODUCT(('Workout Log'!$A$4:$A$500>=TODAY()-14)*('Workout Log'!$A$4:$A$500<>"")*(IFERROR(VLOOKUP('Workout Log'!H$4:H$500,'Exercise Library'!$B$4:$D$200,3,FALSE()),"")=A8))+SUMPRODUCT(('Workout Log'!$A$4:$A$500>=TODAY()-14)*('Workout Log'!$A$4:$A$500<>"")*(IFERROR(VLOOKUP('Workout Log'!I$4:I$500,'Exercise Library'!$B$4:$C$200,2,FALSE()),"")=A8))+SUMPRODUCT(('Workout Log'!$A$4:$A$500>=TODAY()-14)*('Workout Log'!$A$4:$A$500<>"")*(IFERROR(VLOOKUP('Workout Log'!I$4:I$500,'Exercise Library'!$B$4:$D$200,3,FALSE()),"")=A8))+SUMPRODUCT(('Workout Log'!$A$4:$A$500>=TODAY()-14)*('Workout Log'!$A$4:$A$500<>"")*(IFERROR(VLOOKUP('Workout Log'!J$4:J$500,'Exercise Library'!$B$4:$C$200,2,FALSE()),"")=A8))+SUMPRODUCT(('Workout Log'!$A$4:$A$500>=TODAY()-14)*('Workout Log'!$A$4:$A$500<>"")*(IFERROR(VLOOKUP('Workout Log'!J$4:J$500,'Exercise Library'!$B$4:$D$200,3,FALSE()),"")=A8))+SUMPRODUCT(('Workout Log'!$A$4:$A$500>=TODAY()-14)*('Workout Log'!$A$4:$A$500<>"")*(IFERROR(VLOOKUP('Workout Log'!K$4:K$500,'Exercise Library'!$B$4:$C$200,2,FALSE()),"")=A8))+SUMPRODUCT(('Workout Log'!$A$4:$A$500>=TODAY()-14)*('Workout Log'!$A$4:$A$500<>"")*(IFERROR(VLOOKUP('Workout Log'!K$4:K$500,'Exercise Library'!$B$4:$D$200,3,FALSE()),"")=A8))+SUMPRODUCT(('Workout Log'!$A$4:$A$500>=TODAY()-14)*('Workout Log'!$A$4:$A$500<>"")*(IFERROR(VLOOKUP('Workout Log'!L$4:L$500,'Exercise Library'!$B$4:$C$200,2,FALSE()),"")=A8))+SUMPRODUCT(('Workout Log'!$A$4:$A$500>=TODAY()-14)*('Workout Log'!$A$4:$A$500<>"")*(IFERROR(VLOOKUP('Workout Log'!L$4:L$500,'Exercise Library'!$B$4:$D$200,3,FALSE()),"")=A8))+SUMPRODUCT(('Workout Log'!$A$4:$A$500>=TODAY()-14)*('Workout Log'!$A$4:$A$500<>"")*(IFERROR(VLOOKUP('Workout Log'!M$4:M$500,'Exercise Library'!$B$4:$C$200,2,FALSE()),"")=A8))+SUMPRODUCT(('Workout Log'!$A$4:$A$500>=TODAY()-14)*('Workout Log'!$A$4:$A$500<>"")*(IFERROR(VLOOKUP('Workout Log'!M$4:M$500,'Exercise Library'!$B$4:$D$200,3,FALSE()),"")=A8)) -> 0 | D8: =SUMPRODUCT(('Workout Log'!$A$4:$A$500>=TODAY()-30)*('Workout Log'!$A$4:$A$500<>"")*(IFERROR(VLOOKUP('Workout Log'!F$4:F$500,'Exercise Library'!$B$4:$C$200,2,FALSE()),"")=A8))+SUMPRODUCT(('Workout Log'!$A$4:$A$500>=TODAY()-30)*('Workout Log'!$A$4:$A$500<>"")*(IFERROR(VLOOKUP('Workout Log'!F$4:F$500,'Exercise Library'!$B$4:$D$200,3,FALSE()),"")=A8))+SUMPRODUCT(('Workout Log'!$A$4:$A$500>=TODAY()-30)*('Workout Log'!$A$4:$A$500<>"")*(IFERROR(VLOOKUP('Workout Log'!G$4:G$500,'Exercise Library'!$B$4:$C$200,2,FALSE()),"")=A8))+SUMPRODUCT(('Workout Log'!$A$4:$A$500>=TODAY()-30)*('Workout Log'!$A$4:$A$500<>"")*(IFERROR(VLOOKUP('Workout Log'!G$4:G$500,'Exercise Library'!$B$4:$D$200,3,FALSE()),"")=A8))+SUMPRODUCT(('Workout Log'!$A$4:$A$500>=TODAY()-30)*('Workout Log'!$A$4:$A$500<>"")*(IFERROR(VLOOKUP('Workout Log'!H$4:H$500,'Exercise Library'!$B$4:$C$200,2,FALSE()),"")=A8))+SUMPRODUCT(('Workout Log'!$A$4:$A$500>=TODAY()-30)*('Workout Log'!$A$4:$A$500<>"")*(IFERROR(VLOOKUP('Workout Log'!H$4:H$500,'Exercise Library'!$B$4:$D$200,3,FALSE()),"")=A8))+SUMPRODUCT(('Workout Log'!$A$4:$A$500>=TODAY()-30)*('Workout Log'!$A$4:$A$500<>"")*(IFERROR(VLOOKUP('Workout Log'!I$4:I$500,'Exercise Library'!$B$4:$C$200,2,FALSE()),"")=A8))+SUMPRODUCT(('Workout Log'!$A$4:$A$500>=TODAY()-30)*('Workout Log'!$A$4:$A$500<>"")*(IFERROR(VLOOKUP('Workout Log'!I$4:I$500,'Exercise Library'!$B$4:$D$200,3,FALSE()),"")=A8))+SUMPRODUCT(('Workout Log'!$A$4:$A$500>=TODAY()-30)*('Workout Log'!$A$4:$A$500<>"")*(IFERROR(VLOOKUP('Workout Log'!J$4:J$500,'Exercise Library'!$B$4:$C$200,2,FALSE()),"")=A8))+SUMPRODUCT(('Workout Log'!$A$4:$A$500>=TODAY()-30)*('Workout Log'!$A$4:$A$500<>"")*(IFERROR(VLOOKUP('Workout Log'!J$4:J$500,'Exercise Library'!$B$4:$D$200,3,FALSE()),"")=A8))+SUMPRODUCT(('Workout Log'!$A$4:$A$500>=TODAY()-30)*('Workout Log'!$A$4:$A$500<>"")*(IFERROR(VLOOKUP('Workout Log'!K$4:K$500,'Exercise Library'!$B$4:$C$200,2,FALSE()),"")=A8))+SUMPRODUCT(('Workout Log'!$A$4:$A$500>=TODAY()-30)*('Workout Log'!$A$4:$A$500<>"")*(IFERROR(VLOOKUP('Workout Log'!K$4:K$500,'Exercise Library'!$B$4:$D$200,3,FALSE()),"")=A8))+SUMPRODUCT(('Workout Log'!$A$4:$A$500>=TODAY()-30)*('Workout Log'!$A$4:$A$500<>"")*(IFERROR(VLOOKUP('Workout Log'!L$4:L$500,'Exercise Library'!$B$4:$C$200,2,FALSE()),"")=A8))+SUMPRODUCT(('Workout Log'!$A$4:$A$500>=TODAY()-30)*('Workout Log'!$A$4:$A$500<>"")*(IFERROR(VLOOKUP('Workout Log'!L$4:L$500,'Exercise Library'!$B$4:$D$200,3,FALSE()),"")=A8))+SUMPRODUCT(('Workout Log'!$A$4:$A$500>=TODAY()-30)*('Workout Log'!$A$4:$A$500<>"")*(IFERROR(VLOOKUP('Workout Log'!M$4:M$500,'Exercise Library'!$B$4:$C$200,2,FALSE()),"")=A8))+SUMPRODUCT(('Workout Log'!$A$4:$A$500>=TODAY()-30)*('Workout Log'!$A$4:$A$500<>"")*(IFERROR(VLOOKUP('Workout Log'!M$4:M$500,'Exercise Library'!$B$4:$D$200,3,FALSE()),"")=A8)) -> 0 | E8: =SUMPRODUCT(('Workout Log'!$A$4:$A$500>0)*('Workout Log'!$A$4:$A$500<>"")*(IFERROR(VLOOKUP('Workout Log'!F$4:F$500,'Exercise Library'!$B$4:$C$200,2,FALSE()),"")=A8))+SUMPRODUCT(('Workout Log'!$A$4:$A$500>0)*('Workout Log'!$A$4:$A$500<>"")*(IFERROR(VLOOKUP('Workout Log'!F$4:F$500,'Exercise Library'!$B$4:$D$200,3,FALSE()),"")=A8))+SUMPRODUCT(('Workout Log'!$A$4:$A$500>0)*('Workout Log'!$A$4:$A$500<>"")*(IFERROR(VLOOKUP('Workout Log'!G$4:G$500,'Exercise Library'!$B$4:$C$200,2,FALSE()),"")=A8))+SUMPRODUCT(('Workout Log'!$A$4:$A$500>0)*('Workout Log'!$A$4:$A$500<>"")*(IFERROR(VLOOKUP('Workout Log'!G$4:G$500,'Exercise Library'!$B$4:$D$200,3,FALSE()),"")=A8))+SUMPRODUCT(('Workout Log'!$A$4:$A$500>0)*('Workout Log'!$A$4:$A$500<>"")*(IFERROR(VLOOKUP('Workout Log'!H$4:H$500,'Exercise Library'!$B$4:$C$200,2,FALSE()),"")=A8))+SUMPRODUCT(('Workout Log'!$A$4:$A$500>0)*('Workout Log'!$A$4:$A$500<>"")*(IFERROR(VLOOKUP('Workout Log'!H$4:H$500,'Exercise Library'!$B$4:$D$200,3,FALSE()),"")=A8))+SUMPRODUCT(('Workout Log'!$A$4:$A$500>0)*('Workout Log'!$A$4:$A$500<>"")*(IFERROR(VLOOKUP('Workout Log'!I$4:I$500,'Exercise Library'!$B$4:$C$200,2,FALSE()),"")=A8))+SUMPRODUCT(('Workout Log'!$A$4:$A$500>0)*('Workout Log'!$A$4:$A$500<>"")*(IFERROR(VLOOKUP('Workout Log'!I$4:I$500,'Exercise Library'!$B$4:$D$200,3,FALSE()),"")=A8))+SUMPRODUCT(('Workout Log'!$A$4:$A$500>0)*('Workout Log'!$A$4:$A$500<>"")*(IFERROR(VLOOKUP('Workout Log'!J$4:J$500,'Exercise Library'!$B$4:$C$200,2,FALSE()),"")=A8))+SUMPRODUCT(('Workout Log'!$A$4:$A$500>0)*('Workout Log'!$A$4:$A$500<>"")*(IFERROR(VLOOKUP('Workout Log'!J$4:J$500,'Exercise Library'!$B$4:$D$200,3,FALSE()),"")=A8))+SUMPRODUCT(('Workout Log'!$A$4:$A$500>0)*('Workout Log'!$A$4:$A$500<>"")*(IFERROR(VLOOKUP('Workout Log'!K$4:K$500,'Exercise Library'!$B$4:$C$200,2,FALSE()),"")=A8))+SUMPRODUCT(('Workout Log'!$A$4:$A$500>0)*('Workout Log'!$A$4:$A$500<>"")*(IFERROR(VLOOKUP('Workout Log'!K$4:K$500,'Exercise Library'!$B$4:$D$200,3,FALSE()),"")=A8))+SUMPRODUCT(('Workout Log'!$A$4:$A$500>0)*('Workout Log'!$A$4:$A$500<>"")*(IFERROR(VLOOKUP('Workout Log'!L$4:L$500,'Exercise Library'!$B$4:$C$200,2,FALSE()),"")=A8))+SUMPRODUCT(('Workout Log'!$A$4:$A$500>0)*('Workout Log'!$A$4:$A$500<>"")*(IFERROR(VLOOKUP('Workout Log'!L$4:L$500,'Exercise Library'!$B$4:$D$200,3,FALSE()),"")=A8))+SUMPRODUCT(('Workout Log'!$A$4:$A$500>0)*('Workout Log'!$A$4:$A$500<>"")*(IFERROR(VLOOKUP('Workout Log'!M$4:M$500,'Exercise Library'!$B$4:$C$200,2,FALSE()),"")=A8))+SUMPRODUCT(('Workout Log'!$A$4:$A$500>0)*('Workout Log'!$A$4:$A$500<>"")*(IFERROR(VLOOKUP('Workout Log'!M$4:M$500,'Exercise Library'!$B$4:$D$200,3,FALSE()),"")=A8)) -> 0 | F8: =IF(E8=0,"Never",IFERROR(TODAY()-MAX(B8*0+TODAY()-7),"N/A")) -> Never | G8: 2 | H8: =MAX(0, G8-B8) -> 2
A9: Push (Horizontal) | B9: =SUMPRODUCT(('Workout Log'!$A$4:$A$500>=TODAY()-7)*('Workout Log'!$A$4:$A$500<>"")*(IFERROR(VLOOKUP('Workout Log'!F$4:F$500,'Exercise Library'!$B$4:$C$200,2,FALSE()),"")=A9))+SUMPRODUCT(('Workout Log'!$A$4:$A$500>=TODAY()-7)*('Workout Log'!$A$4:$A$500<>"")*(IFERROR(VLOOKUP('Workout Log'!F$4:F$500,'Exercise Library'!$B$4:$D$200,3,FALSE()),"")=A9))+SUMPRODUCT(('Workout Log'!$A$4:$A$500>=TODAY()-7)*('Workout Log'!$A$4:$A$500<>"")*(IFERROR(VLOOKUP('Workout Log'!G$4:G$500,'Exercise Library'!$B$4:$C$200,2,FALSE()),"")=A9))+SUMPRODUCT(('Workout Log'!$A$4:$A$500>=TODAY()-7)*('Workout Log'!$A$4:$A$500<>"")*(IFERROR(VLOOKUP('Workout Log'!G$4:G$500,'Exercise Library'!$B$4:$D$200,3,FALSE()),"")=A9))+SUMPRODUCT(('Workout Log'!$A$4:$A$500>=TODAY()-7)*('Workout Log'!$A$4:$A$500<>"")*(IFERROR(VLOOKUP('Workout Log'!H$4:H$500,'Exercise Library'!$B$4:$C$200,2,FALSE()),"")=A9))+SUMPRODUCT(('Workout Log'!$A$4:$A$500>=TODAY()-7)*('Workout Log'!$A$4:$A$500<>"")*(IFERROR(VLOOKUP('Workout Log'!H$4:H$500,'Exercise Library'!$B$4:$D$200,3,FALSE()),"")=A9))+SUMPRODUCT(('Workout Log'!$A$4:$A$500>=TODAY()-7)*('Workout Log'!$A$4:$A$500<>"")*(IFERROR(VLOOKUP('Workout Log'!I$4:I$500,'Exercise Library'!$B$4:$C$200,2,FALSE()),"")=A9))+SUMPRODUCT(('Workout Log'!$A$4:$A$500>=TODAY()-7)*('Workout Log'!$A$4:$A$500<>"")*(IFERROR(VLOOKUP('Workout Log'!I$4:I$500,'Exercise Library'!$B$4:$D$200,3,FALSE()),"")=A9))+SUMPRODUCT(('Workout Log'!$A$4:$A$500>=TODAY()-7)*('Workout Log'!$A$4:$A$500<>"")*(IFERROR(VLOOKUP('Workout Log'!J$4:J$500,'Exercise Library'!$B$4:$C$200,2,FALSE()),"")=A9))+SUMPRODUCT(('Workout Log'!$A$4:$A$500>=TODAY()-7)*('Workout Log'!$A$4:$A$500<>"")*(IFERROR(VLOOKUP('Workout Log'!J$4:J$500,'Exercise Library'!$B$4:$D$200,3,FALSE()),"")=A9))+SUMPRODUCT(('Workout Log'!$A$4:$A$500>=TODAY()-7)*('Workout Log'!$A$4:$A$500<>"")*(IFERROR(VLOOKUP('Workout Log'!K$4:K$500,'Exercise Library'!$B$4:$C$200,2,FALSE()),"")=A9))+SUMPRODUCT(('Workout Log'!$A$4:$A$500>=TODAY()-7)*('Workout Log'!$A$4:$A$500<>"")*(IFERROR(VLOOKUP('Workout Log'!K$4:K$500,'Exercise Library'!$B$4:$D$200,3,FALSE()),"")=A9))+SUMPRODUCT(('Workout Log'!$A$4:$A$500>=TODAY()-7)*('Workout Log'!$A$4:$A$500<>"")*(IFERROR(VLOOKUP('Workout Log'!L$4:L$500,'Exercise Library'!$B$4:$C$200,2,FALSE()),"")=A9))+SUMPRODUCT(('Workout Log'!$A$4:$A$500>=TODAY()-7)*('Workout Log'!$A$4:$A$500<>"")*(IFERROR(VLOOKUP('Workout Log'!L$4:L$500,'Exercise Library'!$B$4:$D$200,3,FALSE()),"")=A9))+SUMPRODUCT(('Workout Log'!$A$4:$A$500>=TODAY()-7)*('Workout Log'!$A$4:$A$500<>"")*(IFERROR(VLOOKUP('Workout Log'!M$4:M$500,'Exercise Library'!$B$4:$C$200,2,FALSE()),"")=A9))+SUMPRODUCT(('Workout Log'!$A$4:$A$500>=TODAY()-7)*('Workout Log'!$A$4:$A$500<>"")*(IFERROR(VLOOKUP('Workout Log'!M$4:M$500,'Exercise Library'!$B$4:$D$200,3,FALSE()),"")=A9)) -> 0 | C9: =SUMPRODUCT(('Workout Log'!$A$4:$A$500>=TODAY()-14)*('Workout Log'!$A$4:$A$500<>"")*(IFERROR(VLOOKUP('Workout Log'!F$4:F$500,'Exercise Library'!$B$4:$C$200,2,FALSE()),"")=A9))+SUMPRODUCT(('Workout Log'!$A$4:$A$500>=TODAY()-14)*('Workout Log'!$A$4:$A$500<>"")*(IFERROR(VLOOKUP('Workout Log'!F$4:F$500,'Exercise Library'!$B$4:$D$200,3,FALSE()),"")=A9))+SUMPRODUCT(('Workout Log'!$A$4:$A$500>=TODAY()-14)*('Workout Log'!$A$4:$A$500<>"")*(IFERROR(VLOOKUP('Workout Log'!G$4:G$500,'Exercise Library'!$B$4:$C$200,2,FALSE()),"")=A9))+SUMPRODUCT(('Workout Log'!$A$4:$A$500>=TODAY()-14)*('Workout Log'!$A$4:$A$500<>"")*(IFERROR(VLOOKUP('Workout Log'!G$4:G$500,'Exercise Library'!$B$4:$D$200,3,FALSE()),"")=A9))+SUMPRODUCT(('Workout Log'!$A$4:$A$500>=TODAY()-14)*('Workout Log'!$A$4:$A$500<>"")*(IFERROR(VLOOKUP('Workout Log'!H$4:H$500,'Exercise Library'!$B$4:$C$200,2,FALSE()),"")=A9))+SUMPRODUCT(('Workout Log'!$A$4:$A$500>=TODAY()-14)*('Workout Log'!$A$4:$A$500<>"")*(IFERROR(VLOOKUP('Workout Log'!H$4:H$500,'Exercise Library'!$B$4:$D$200,3,FALSE()),"")=A9))+SUMPRODUCT(('Workout Log'!$A$4:$A$500>=TODAY()-14)*('Workout Log'!$A$4:$A$500<>"")*(IFERROR(VLOOKUP('Workout Log'!I$4:I$500,'Exercise Library'!$B$4:$C$200,2,FALSE()),"")=A9))+SUMPRODUCT(('Workout Log'!$A$4:$A$500>=TODAY()-14)*('Workout Log'!$A$4:$A$500<>"")*(IFERROR(VLOOKUP('Workout Log'!I$4:I$500,'Exercise Library'!$B$4:$D$200,3,FALSE()),"")=A9))+SUMPRODUCT(('Workout Log'!$A$4:$A$500>=TODAY()-14)*('Workout Log'!$A$4:$A$500<>"")*(IFERROR(VLOOKUP('Workout Log'!J$4:J$500,'Exercise Library'!$B$4:$C$200,2,FALSE()),"")=A9))+SUMPRODUCT(('Workout Log'!$A$4:$A$500>=TODAY()-14)*('Workout Log'!$A$4:$A$500<>"")*(IFERROR(VLOOKUP('Workout Log'!J$4:J$500,'Exercise Library'!$B$4:$D$200,3,FALSE()),"")=A9))+SUMPRODUCT(('Workout Log'!$A$4:$A$500>=TODAY()-14)*('Workout Log'!$A$4:$A$500<>"")*(IFERROR(VLOOKUP('Workout Log'!K$4:K$500,'Exercise Library'!$B$4:$C$200,2,FALSE()),"")=A9))+SUMPRODUCT(('Workout Log'!$A$4:$A$500>=TODAY()-14)*('Workout Log'!$A$4:$A$500<>"")*(IFERROR(VLOOKUP('Workout Log'!K$4:K$500,'Exercise Library'!$B$4:$D$200,3,FALSE()),"")=A9))+SUMPRODUCT(('Workout Log'!$A$4:$A$500>=TODAY()-14)*('Workout Log'!$A$4:$A$500<>"")*(IFERROR(VLOOKUP('Workout Log'!L$4:L$500,'Exercise Library'!$B$4:$C$200,2,FALSE()),"")=A9))+SUMPRODUCT(('Workout Log'!$A$4:$A$500>=TODAY()-14)*('Workout Log'!$A$4:$A$500<>"")*(IFERROR(VLOOKUP('Workout Log'!L$4:L$500,'Exercise Library'!$B$4:$D$200,3,FALSE()),"")=A9))+SUMPRODUCT(('Workout Log'!$A$4:$A$500>=TODAY()-14)*('Workout Log'!$A$4:$A$500<>"")*(IFERROR(VLOOKUP('Workout Log'!M$4:M$500,'Exercise Library'!$B$4:$C$200,2,FALSE()),"")=A9))+SUMPRODUCT(('Workout Log'!$A$4:$A$500>=TODAY()-14)*('Workout Log'!$A$4:$A$500<>"")*(IFERROR(VLOOKUP('Workout Log'!M$4:M$500,'Exercise Library'!$B$4:$D$200,3,FALSE()),"")=A9)) -> 0 | D9: =SUMPRODUCT(('Workout Log'!$A$4:$A$500>=TODAY()-30)*('Workout Log'!$A$4:$A$500<>"")*(IFERROR(VLOOKUP('Workout Log'!F$4:F$500,'Exercise Library'!$B$4:$C$200,2,FALSE()),"")=A9))+SUMPRODUCT(('Workout Log'!$A$4:$A$500>=TODAY()-30)*('Workout Log'!$A$4:$A$500<>"")*(IFERROR(VLOOKUP('Workout Log'!F$4:F$500,'Exercise Library'!$B$4:$D$200,3,FALSE()),"")=A9))+SUMPRODUCT(('Workout Log'!$A$4:$A$500>=TODAY()-30)*('Workout Log'!$A$4:$A$500<>"")*(IFERROR(VLOOKUP('Workout Log'!G$4:G$500,'Exercise Library'!$B$4:$C$200,2,FALSE()),"")=A9))+SUMPRODUCT(('Workout Log'!$A$4:$A$500>=TODAY()-30)*('Workout Log'!$A$4:$A$500<>"")*(IFERROR(VLOOKUP('Workout Log'!G$4:G$500,'Exercise Library'!$B$4:$D$200,3,FALSE()),"")=A9))+SUMPRODUCT(('Workout Log'!$A$4:$A$500>=TODAY()-30)*('Workout Log'!$A$4:$A$500<>"")*(IFERROR(VLOOKUP('Workout Log'!H$4:H$500,'Exercise Library'!$B$4:$C$200,2,FALSE()),"")=A9))+SUMPRODUCT(('Workout Log'!$A$4:$A$500>=TODAY()-30)*('Workout Log'!$A$4:$A$500<>"")*(IFERROR(VLOOKUP('Workout Log'!H$4:H$500,'Exercise Library'!$B$4:$D$200,3,FALSE()),"")=A9))+SUMPRODUCT(('Workout Log'!$A$4:$A$500>=TODAY()-30)*('Workout Log'!$A$4:$A$500<>"")*(IFERROR(VLOOKUP('Workout Log'!I$4:I$500,'Exercise Library'!$B$4:$C$200,2,FALSE()),"")=A9))+SUMPRODUCT(('Workout Log'!$A$4:$A$500>=TODAY()-30)*('Workout Log'!$A$4:$A$500<>"")*(IFERROR(VLOOKUP('Workout Log'!I$4:I$500,'Exercise Library'!$B$4:$D$200,3,FALSE()),"")=A9))+SUMPRODUCT(('Workout Log'!$A$4:$A$500>=TODAY()-30)*('Workout Log'!$A$4:$A$500<>"")*(IFERROR(VLOOKUP('Workout Log'!J$4:J$500,'Exercise Library'!$B$4:$C$200,2,FALSE()),"")=A9))+SUMPRODUCT(('Workout Log'!$A$4:$A$500>=TODAY()-30)*('Workout Log'!$A$4:$A$500<>"")*(IFERROR(VLOOKUP('Workout Log'!J$4:J$500,'Exercise Library'!$B$4:$D$200,3,FALSE()),"")=A9))+SUMPRODUCT(('Workout Log'!$A$4:$A$500>=TODAY()-30)*('Workout Log'!$A$4:$A$500<>"")*(IFERROR(VLOOKUP('Workout Log'!K$4:K$500,'Exercise Library'!$B$4:$C$200,2,FALSE()),"")=A9))+SUMPRODUCT(('Workout Log'!$A$4:$A$500>=TODAY()-30)*('Workout Log'!$A$4:$A$500<>"")*(IFERROR(VLOOKUP('Workout Log'!K$4:K$500,'Exercise Library'!$B$4:$D$200,3,FALSE()),"")=A9))+SUMPRODUCT(('Workout Log'!$A$4:$A$500>=TODAY()-30)*('Workout Log'!$A$4:$A$500<>"")*(IFERROR(VLOOKUP('Workout Log'!L$4:L$500,'Exercise Library'!$B$4:$C$200,2,FALSE()),"")=A9))+SUMPRODUCT(('Workout Log'!$A$4:$A$500>=TODAY()-30)*('Workout Log'!$A$4:$A$500<>"")*(IFERROR(VLOOKUP('Workout Log'!L$4:L$500,'Exercise Library'!$B$4:$D$200,3,FALSE()),"")=A9))+SUMPRODUCT(('Workout Log'!$A$4:$A$500>=TODAY()-30)*('Workout Log'!$A$4:$A$500<>"")*(IFERROR(VLOOKUP('Workout Log'!M$4:M$500,'Exercise Library'!$B$4:$C$200,2,FALSE()),"")=A9))+SUMPRODUCT(('Workout Log'!$A$4:$A$500>=TODAY()-30)*('Workout Log'!$A$4:$A$500<>"")*(IFERROR(VLOOKUP('Workout Log'!M$4:M$500,'Exercise Library'!$B$4:$D$200,3,FALSE()),"")=A9)) -> 0 | E9: =SUMPRODUCT(('Workout Log'!$A$4:$A$500>0)*('Workout Log'!$A$4:$A$500<>"")*(IFERROR(VLOOKUP('Workout Log'!F$4:F$500,'Exercise Library'!$B$4:$C$200,2,FALSE()),"")=A9))+SUMPRODUCT(('Workout Log'!$A$4:$A$500>0)*('Workout Log'!$A$4:$A$500<>"")*(IFERROR(VLOOKUP('Workout Log'!F$4:F$500,'Exercise Library'!$B$4:$D$200,3,FALSE()),"")=A9))+SUMPRODUCT(('Workout Log'!$A$4:$A$500>0)*('Workout Log'!$A$4:$A$500<>"")*(IFERROR(VLOOKUP('Workout Log'!G$4:G$500,'Exercise Library'!$B$4:$C$200,2,FALSE()),"")=A9))+SUMPRODUCT(('Workout Log'!$A$4:$A$500>0)*('Workout Log'!$A$4:$A$500<>"")*(IFERROR(VLOOKUP('Workout Log'!G$4:G$500,'Exercise Library'!$B$4:$D$200,3,FALSE()),"")=A9))+SUMPRODUCT(('Workout Log'!$A$4:$A$500>0)*('Workout Log'!$A$4:$A$500<>"")*(IFERROR(VLOOKUP('Workout Log'!H$4:H$500,'Exercise Library'!$B$4:$C$200,2,FALSE()),"")=A9))+SUMPRODUCT(('Workout Log'!$A$4:$A$500>0)*('Workout Log'!$A$4:$A$500<>"")*(IFERROR(VLOOKUP('Workout Log'!H$4:H$500,'Exercise Library'!$B$4:$D$200,3,FALSE()),"")=A9))+SUMPRODUCT(('Workout Log'!$A$4:$A$500>0)*('Workout Log'!$A$4:$A$500<>"")*(IFERROR(VLOOKUP('Workout Log'!I$4:I$500,'Exercise Library'!$B$4:$C$200,2,FALSE()),"")=A9))+SUMPRODUCT(('Workout Log'!$A$4:$A$500>0)*('Workout Log'!$A$4:$A$500<>"")*(IFERROR(VLOOKUP('Workout Log'!I$4:I$500,'Exercise Library'!$B$4:$D$200,3,FALSE()),"")=A9))+SUMPRODUCT(('Workout Log'!$A$4:$A$500>0)*('Workout Log'!$A$4:$A$500<>"")*(IFERROR(VLOOKUP('Workout Log'!J$4:J$500,'Exercise Library'!$B$4:$C$200,2,FALSE()),"")=A9))+SUMPRODUCT(('Workout Log'!$A$4:$A$500>0)*('Workout Log'!$A$4:$A$500<>"")*(IFERROR(VLOOKUP('Workout Log'!J$4:J$500,'Exercise Library'!$B$4:$D$200,3,FALSE()),"")=A9))+SUMPRODUCT(('Workout Log'!$A$4:$A$500>0)*('Workout Log'!$A$4:$A$500<>"")*(IFERROR(VLOOKUP('Workout Log'!K$4:K$500,'Exercise Library'!$B$4:$C$200,2,FALSE()),"")=A9))+SUMPRODUCT(('Workout Log'!$A$4:$A$500>0)*('Workout Log'!$A$4:$A$500<>"")*(IFERROR(VLOOKUP('Workout Log'!K$4:K$500,'Exercise Library'!$B$4:$D$200,3,FALSE()),"")=A9))+SUMPRODUCT(('Workout Log'!$A$4:$A$500>0)*('Workout Log'!$A$4:$A$500<>"")*(IFERROR(VLOOKUP('Workout Log'!L$4:L$500,'Exercise Library'!$B$4:$C$200,2,FALSE()),"")=A9))+SUMPRODUCT(('Workout Log'!$A$4:$A$500>0)*('Workout Log'!$A$4:$A$500<>"")*(IFERROR(VLOOKUP('Workout Log'!L$4:L$500,'Exercise Library'!$B$4:$D$200,3,FALSE()),"")=A9))+SUMPRODUCT(('Workout Log'!$A$4:$A$500>0)*('Workout Log'!$A$4:$A$500<>"")*(IFERROR(VLOOKUP('Workout Log'!M$4:M$500,'Exercise Library'!$B$4:$C$200,2,FALSE()),"")=A9))+SUMPRODUCT(('Workout Log'!$A$4:$A$500>0)*('Workout Log'!$A$4:$A$500<>"")*(IFERROR(VLOOKUP('Workout Log'!M$4:M$500,'Exercise Library'!$B$4:$D$200,3,FALSE()),"")=A9)) -> 0 | F9: =IF(E9=0,"Never",IFERROR(TODAY()-MAX(B9*0+TODAY()-7),"N/A")) -> Never | G9: 2 | H9: =MAX(0, G9-B9) -> 2
A10: Push (Vertical) | B10: =SUMPRODUCT(('Workout Log'!$A$4:$A$500>=TODAY()-7)*('Workout Log'!$A$4:$A$500<>"")*(IFERROR(VLOOKUP('Workout Log'!F$4:F$500,'Exercise Library'!$B$4:$C$200,2,FALSE()),"")=A10))+SUMPRODUCT(('Workout Log'!$A$4:$A$500>=TODAY()-7)*('Workout Log'!$A$4:$A$500<>"")*(IFERROR(VLOOKUP('Workout Log'!F$4:F$500,'Exercise Library'!$B$4:$D$200,3,FALSE()),"")=A10))+SUMPRODUCT(('Workout Log'!$A$4:$A$500>=TODAY()-7)*('Workout Log'!$A$4:$A$500<>"")*(IFERROR(VLOOKUP('Workout Log'!G$4:G$500,'Exercise Library'!$B$4:$C$200,2,FALSE()),"")=A10))+SUMPRODUCT(('Workout Log'!$A$4:$A$500>=TODAY()-7)*('Workout Log'!$A$4:$A$500<>"")*(IFERROR(VLOOKUP('Workout Log'!G$4:G$500,'Exercise Library'!$B$4:$D$200,3,FALSE()),"")=A10))+SUMPRODUCT(('Workout Log'!$A$4:$A$500>=TODAY()-7)*('Workout Log'!$A$4:$A$500<>"")*(IFERROR(VLOOKUP('Workout Log'!H$4:H$500,'Exercise Library'!$B$4:$C$200,2,FALSE()),"")=A10))+SUMPRODUCT(('Workout Log'!$A$4:$A$500>=TODAY()-7)*('Workout Log'!$A$4:$A$500<>"")*(IFERROR(VLOOKUP('Workout Log'!H$4:H$500,'Exercise Library'!$B$4:$D$200,3,FALSE()),"")=A10))+SUMPRODUCT(('Workout Log'!$A$4:$A$500>=TODAY()-7)*('Workout Log'!$A$4:$A$500<>"")*(IFERROR(VLOOKUP('Workout Log'!I$4:I$500,'Exercise Library'!$B$4:$C$200,2,FALSE()),"")=A10))+SUMPRODUCT(('Workout Log'!$A$4:$A$500>=TODAY()-7)*('Workout Log'!$A$4:$A$500<>"")*(IFERROR(VLOOKUP('Workout Log'!I$4:I$500,'Exercise Library'!$B$4:$D$200,3,FALSE()),"")=A10))+SUMPRODUCT(('Workout Log'!$A$4:$A$500>=TODAY()-7)*('Workout Log'!$A$4:$A$500<>"")*(IFERROR(VLOOKUP('Workout Log'!J$4:J$500,'Exercise Library'!$B$4:$C$200,2,FALSE()),"")=A10))+SUMPRODUCT(('Workout Log'!$A$4:$A$500>=TODAY()-7)*('Workout Log'!$A$4:$A$500<>"")*(IFERROR(VLOOKUP('Workout Log'!J$4:J$500,'Exercise Library'!$B$4:$D$200,3,FALSE()),"")=A10))+SUMPRODUCT(('Workout Log'!$A$4:$A$500>=TODAY()-7)*('Workout Log'!$A$4:$A$500<>"")*(IFERROR(VLOOKUP('Workout Log'!K$4:K$500,'Exercise Library'!$B$4:$C$200,2,FALSE()),"")=A10))+SUMPRODUCT(('Workout Log'!$A$4:$A$500>=TODAY()-7)*('Workout Log'!$A$4:$A$500<>"")*(IFERROR(VLOOKUP('Workout Log'!K$4:K$500,'Exercise Library'!$B$4:$D$200,3,FALSE()),"")=A10))+SUMPRODUCT(('Workout Log'!$A$4:$A$500>=TODAY()-7)*('Workout Log'!$A$4:$A$500<>"")*(IFERROR(VLOOKUP('Workout Log'!L$4:L$500,'Exercise Library'!$B$4:$C$200,2,FALSE()),"")=A10))+SUMPRODUCT(('Workout Log'!$A$4:$A$500>=TODAY()-7)*('Workout Log'!$A$4:$A$500<>"")*(IFERROR(VLOOKUP('Workout Log'!L$4:L$500,'Exercise Library'!$B$4:$D$200,3,FALSE()),"")=A10))+SUMPRODUCT(('Workout Log'!$A$4:$A$500>=TODAY()-7)*('Workout Log'!$A$4:$A$500<>"")*(IFERROR(VLOOKUP('Workout Log'!M$4:M$500,'Exercise Library'!$B$4:$C$200,2,FALSE()),"")=A10))+SUMPRODUCT(('Workout Log'!$A$4:$A$500>=TODAY()-7)*('Workout Log'!$A$4:$A$500<>"")*(IFERROR(VLOOKUP('Workout Log'!M$4:M$500,'Exercise Library'!$B$4:$D$200,3,FALSE()),"")=A10)) -> 0 | C10: =SUMPRODUCT(('Workout Log'!$A$4:$A$500>=TODAY()-14)*('Workout Log'!$A$4:$A$500<>"")*(IFERROR(VLOOKUP('Workout Log'!F$4:F$500,'Exercise Library'!$B$4:$C$200,2,FALSE()),"")=A10))+SUMPRODUCT(('Workout Log'!$A$4:$A$500>=TODAY()-14)*('Workout Log'!$A$4:$A$500<>"")*(IFERROR(VLOOKUP('Workout Log'!F$4:F$500,'Exercise Library'!$B$4:$D$200,3,FALSE()),"")=A10))+SUMPRODUCT(('Workout Log'!$A$4:$A$500>=TODAY()-14)*('Workout Log'!$A$4:$A$500<>"")*(IFERROR(VLOOKUP('Workout Log'!G$4:G$500,'Exercise Library'!$B$4:$C$200,2,FALSE()),"")=A10))+SUMPRODUCT(('Workout Log'!$A$4:$A$500>=TODAY()-14)*('Workout Log'!$A$4:$A$500<>"")*(IFERROR(VLOOKUP('Workout Log'!G$4:G$500,'Exercise Library'!$B$4:$D$200,3,FALSE()),"")=A10))+SUMPRODUCT(('Workout Log'!$A$4:$A$500>=TODAY()-14)*('Workout Log'!$A$4:$A$500<>"")*(IFERROR(VLOOKUP('Workout Log'!H$4:H$500,'Exercise Library'!$B$4:$C$200,2,FALSE()),"")=A10))+SUMPRODUCT(('Workout Log'!$A$4:$A$500>=TODAY()-14)*('Workout Log'!$A$4:$A$500<>"")*(IFERROR(VLOOKUP('Workout Log'!H$4:H$500,'Exercise Library'!$B$4:$D$200,3,FALSE()),"")=A10))+SUMPRODUCT(('Workout Log'!$A$4:$A$500>=TODAY()-14)*('Workout Log'!$A$4:$A$500<>"")*(IFERROR(VLOOKUP('Workout Log'!I$4:I$500,'Exercise Library'!$B$4:$C$200,2,FALSE()),"")=A10))+SUMPRODUCT(('Workout Log'!$A$4:$A$500>=TODAY()-14)*('Workout Log'!$A$4:$A$500<>"")*(IFERROR(VLOOKUP('Workout Log'!I$4:I$500,'Exercise Library'!$B$4:$D$200,3,FALSE()),"")=A10))+SUMPRODUCT(('Workout Log'!$A$4:$A$500>=TODAY()-14)*('Workout Log'!$A$4:$A$500<>"")*(IFERROR(VLOOKUP('Workout Log'!J$4:J$500,'Exercise Library'!$B$4:$C$200,2,FALSE()),"")=A10))+SUMPRODUCT(('Workout Log'!$A$4:$A$500>=TODAY()-14)*('Workout Log'!$A$4:$A$500<>"")*(IFERROR(VLOOKUP('Workout Log'!J$4:J$500,'Exercise Library'!$B$4:$D$200,3,FALSE()),"")=A10))+SUMPRODUCT(('Workout Log'!$A$4:$A$500>=TODAY()-14)*('Workout Log'!$A$4:$A$500<>"")*(IFERROR(VLOOKUP('Workout Log'!K$4:K$500,'Exercise Library'!$B$4:$C$200,2,FALSE()),"")=A10))+SUMPRODUCT(('Workout Log'!$A$4:$A$500>=TODAY()-14)*('Workout Log'!$A$4:$A$500<>"")*(IFERROR(VLOOKUP('Workout Log'!K$4:K$500,'Exercise Library'!$B$4:$D$200,3,FALSE()),"")=A10))+SUMPRODUCT(('Workout Log'!$A$4:$A$500>=TODAY()-14)*('Workout Log'!$A$4:$A$500<>"")*(IFERROR(VLOOKUP('Workout Log'!L$4:L$500,'Exercise Library'!$B$4:$C$200,2,FALSE()),"")=A10))+SUMPRODUCT(('Workout Log'!$A$4:$A$500>=TODAY()-14)*('Workout Log'!$A$4:$A$500<>"")*(IFERROR(VLOOKUP('Workout Log'!L$4:L$500,'Exercise Library'!$B$4:$D$200,3,FALSE()),"")=A10))+SUMPRODUCT(('Workout Log'!$A$4:$A$500>=TODAY()-14)*('Workout Log'!$A$4:$A$500<>"")*(IFERROR(VLOOKUP('Workout Log'!M$4:M$500,'Exercise Library'!$B$4:$C$200,2,FALSE()),"")=A10))+SUMPRODUCT(('Workout Log'!$A$4:$A$500>=TODAY()-14)*('Workout Log'!$A$4:$A$500<>"")*(IFERROR(VLOOKUP('Workout Log'!M$4:M$500,'Exercise Library'!$B$4:$D$200,3,FALSE()),"")=A10)) -> 0 | D10: =SUMPRODUCT(('Workout Log'!$A$4:$A$500>=TODAY()-30)*('Workout Log'!$A$4:$A$500<>"")*(IFERROR(VLOOKUP('Workout Log'!F$4:F$500,'Exercise Library'!$B$4:$C$200,2,FALSE()),"")=A10))+SUMPRODUCT(('Workout Log'!$A$4:$A$500>=TODAY()-30)*('Workout Log'!$A$4:$A$500<>"")*(IFERROR(VLOOKUP('Workout Log'!F$4:F$500,'Exercise Library'!$B$4:$D$200,3,FALSE()),"")=A10))+SUMPRODUCT(('Workout Log'!$A$4:$A$500>=TODAY()-30)*('Workout Log'!$A$4:$A$500<>"")*(IFERROR(VLOOKUP('Workout Log'!G$4:G$500,'Exercise Library'!$B$4:$C$200,2,FALSE()),"")=A10))+SUMPRODUCT(('Workout Log'!$A$4:$A$500>=TODAY()-30)*('Workout Log'!$A$4:$A$500<>"")*(IFERROR(VLOOKUP('Workout Log'!G$4:G$500,'Exercise Library'!$B$4:$D$200,3,FALSE()),"")=A10))+SUMPRODUCT(('Workout Log'!$A$4:$A$500>=TODAY()-30)*('Workout Log'!$A$4:$A$500<>"")*(IFERROR(VLOOKUP('Workout Log'!H$4:H$500,'Exercise Library'!$B$4:$C$200,2,FALSE()),"")=A10))+SUMPRODUCT(('Workout Log'!$A$4:$A$500>=TODAY()-30)*('Workout Log'!$A$4:$A$500<>"")*(IFERROR(VLOOKUP('Workout Log'!H$4:H$500,'Exercise Library'!$B$4:$D$200,3,FALSE()),"")=A10))+SUMPRODUCT(('Workout Log'!$A$4:$A$500>=TODAY()-30)*('Workout Log'!$A$4:$A$500<>"")*(IFERROR(VLOOKUP('Workout Log'!I$4:I$500,'Exercise Library'!$B$4:$C$200,2,FALSE()),"")=A10))+SUMPRODUCT(('Workout Log'!$A$4:$A$500>=TODAY()-30)*('Workout Log'!$A$4:$A$500<>"")*(IFERROR(VLOOKUP('Workout Log'!I$4:I$500,'Exercise Library'!$B$4:$D$200,3,FALSE()),"")=A10))+SUMPRODUCT(('Workout Log'!$A$4:$A$500>=TODAY()-30)*('Workout Log'!$A$4:$A$500<>"")*(IFERROR(VLOOKUP('Workout Log'!J$4:J$500,'Exercise Library'!$B$4:$C$200,2,FALSE()),"")=A10))+SUMPRODUCT(('Workout Log'!$A$4:$A$500>=TODAY()-30)*('Workout Log'!$A$4:$A$500<>"")*(IFERROR(VLOOKUP('Workout Log'!J$4:J$500,'Exercise Library'!$B$4:$D$200,3,FALSE()),"")=A10))+SUMPRODUCT(('Workout Log'!$A$4:$A$500>=TODAY()-30)*('Workout Log'!$A$4:$A$500<>"")*(IFERROR(VLOOKUP('Workout Log'!K$4:K$500,'Exercise Library'!$B$4:$C$200,2,FALSE()),"")=A10))+SUMPRODUCT(('Workout Log'!$A$4:$A$500>=TODAY()-30)*('Workout Log'!$A$4:$A$500<>"")*(IFERROR(VLOOKUP('Workout Log'!K$4:K$500,'Exercise Library'!$B$4:$D$200,3,FALSE()),"")=A10))+SUMPRODUCT(('Workout Log'!$A$4:$A$500>=TODAY()-30)*('Workout Log'!$A$4:$A$500<>"")*(IFERROR(VLOOKUP('Workout Log'!L$4:L$500,'Exercise Library'!$B$4:$C$200,2,FALSE()),"")=A10))+SUMPRODUCT(('Workout Log'!$A$4:$A$500>=TODAY()-30)*('Workout Log'!$A$4:$A$500<>"")*(IFERROR(VLOOKUP('Workout Log'!L$4:L$500,'Exercise Library'!$B$4:$D$200,3,FALSE()),"")=A10))+SUMPRODUCT(('Workout Log'!$A$4:$A$500>=TODAY()-30)*('Workout Log'!$A$4:$A$500<>"")*(IFERROR(VLOOKUP('Workout Log'!M$4:M$500,'Exercise Library'!$B$4:$C$200,2,FALSE()),"")=A10))+SUMPRODUCT(('Workout Log'!$A$4:$A$500>=TODAY()-30)*('Workout Log'!$A$4:$A$500<>"")*(IFERROR(VLOOKUP('Workout Log'!M$4:M$500,'Exercise Library'!$B$4:$D$200,3,FALSE()),"")=A10)) -> 0 | E10: =SUMPRODUCT(('Workout Log'!$A$4:$A$500>0)*('Workout Log'!$A$4:$A$500<>"")*(IFERROR(VLOOKUP('Workout Log'!F$4:F$500,'Exercise Library'!$B$4:$C$200,2,FALSE()),"")=A10))+SUMPRODUCT(('Workout Log'!$A$4:$A$500>0)*('Workout Log'!$A$4:$A$500<>"")*(IFERROR(VLOOKUP('Workout Log'!F$4:F$500,'Exercise Library'!$B$4:$D$200,3,FALSE()),"")=A10))+SUMPRODUCT(('Workout Log'!$A$4:$A$500>0)*('Workout Log'!$A$4:$A$500<>"")*(IFERROR(VLOOKUP('Workout Log'!G$4:G$500,'Exercise Library'!$B$4:$C$200,2,FALSE()),"")=A10))+SUMPRODUCT(('Workout Log'!$A$4:$A$500>0)*('Workout Log'!$A$4:$A$500<>"")*(IFERROR(VLOOKUP('Workout Log'!G$4:G$500,'Exercise Library'!$B$4:$D$200,3,FALSE()),"")=A10))+SUMPRODUCT(('Workout Log'!$A$4:$A$500>0)*('Workout Log'!$A$4:$A$500<>"")*(IFERROR(VLOOKUP('Workout Log'!H$4:H$500,'Exercise Library'!$B$4:$C$200,2,FALSE()),"")=A10))+SUMPRODUCT(('Workout Log'!$A$4:$A$500>0)*('Workout Log'!$A$4:$A$500<>"")*(IFERROR(VLOOKUP('Workout Log'!H$4:H$500,'Exercise Library'!$B$4:$D$200,3,FALSE()),"")=A10))+SUMPRODUCT(('Workout Log'!$A$4:$A$500>0)*('Workout Log'!$A$4:$A$500<>"")*(IFERROR(VLOOKUP('Workout Log'!I$4:I$500,'Exercise Library'!$B$4:$C$200,2,FALSE()),"")=A10))+SUMPRODUCT(('Workout Log'!$A$4:$A$500>0)*('Workout Log'!$A$4:$A$500<>"")*(IFERROR(VLOOKUP('Workout Log'!I$4:I$500,'Exercise Library'!$B$4:$D$200,3,FALSE()),"")=A10))+SUMPRODUCT(('Workout Log'!$A$4:$A$500>0)*('Workout Log'!$A$4:$A$500<>"")*(IFERROR(VLOOKUP('Workout Log'!J$4:J$500,'Exercise Library'!$B$4:$C$200,2,FALSE()),"")=A10))+SUMPRODUCT(('Workout Log'!$A$4:$A$500>0)*('Workout Log'!$A$4:$A$500<>"")*(IFERROR(VLOOKUP('Workout Log'!J$4:J$500,'Exercise Library'!$B$4:$D$200,3,FALSE()),"")=A10))+SUMPRODUCT(('Workout Log'!$A$4:$A$500>0)*('Workout Log'!$A$4:$A$500<>"")*(IFERROR(VLOOKUP('Workout Log'!K$4:K$500,'Exercise Library'!$B$4:$C$200,2,FALSE()),"")=A10))+SUMPRODUCT(('Workout Log'!$A$4:$A$500>0)*('Workout Log'!$A$4:$A$500<>"")*(IFERROR(VLOOKUP('Workout Log'!K$4:K$500,'Exercise Library'!$B$4:$D$200,3,FALSE()),"")=A10))+SUMPRODUCT(('Workout Log'!$A$4:$A$500>0)*('Workout Log'!$A$4:$A$500<>"")*(IFERROR(VLOOKUP('Workout Log'!L$4:L$500,'Exercise Library'!$B$4:$C$200,2,FALSE()),"")=A10))+SUMPRODUCT(('Workout Log'!$A$4:$A$500>0)*('Workout Log'!$A$4:$A$500<>"")*(IFERROR(VLOOKUP('Workout Log'!L$4:L$500,'Exercise Library'!$B$4:$D$200,3,FALSE()),"")=A10))+SUMPRODUCT(('Workout Log'!$A$4:$A$500>0)*('Workout Log'!$A$4:$A$500<>"")*(IFERROR(VLOOKUP('Workout Log'!M$4:M$500,'Exercise Library'!$B$4:$C$200,2,FALSE()),"")=A10))+SUMPRODUCT(('Workout Log'!$A$4:$A$500>0)*('Workout Log'!$A$4:$A$500<>"")*(IFERROR(VLOOKUP('Workout Log'!M$4:M$500,'Exercise Library'!$B$4:$D$200,3,FALSE()),"")=A10)) -> 0 | F10: =IF(E10=0,"Never",IFERROR(TODAY()-MAX(B10*0+TODAY()-7),"N/A")) -> Never | G10: 2 | H10: =MAX(0, G10-B10) -> 2
